{
    "dataType": "CVE_RECORD",
    "dataVersion": "5.0",
    "cveMetadata": {
        "state": "PUBLISHED",
        "cveId": "CVE-2021-3737",
        "assignerOrgId": "53f830b8-0a3f-465b-8143-3b8a9948e749",
        "assignerShortName": "redhat",
        "dateUpdated": "2023-06-30T00:00:00",
        "dateReserved": "2021-08-26T00:00:00",
        "datePublished": "2022-03-04T00:00:00"
    },
    "containers": {
        "cna": {
            "providerMetadata": {
                "orgId": "53f830b8-0a3f-465b-8143-3b8a9948e749",
                "shortName": "redhat",
                "dateUpdated": "2023-06-30T00:00:00"
            },
            "descriptions": [
                {
                    "lang": "en",
                    "value": "A flaw was found in python. An improperly handled HTTP response in the HTTP client code of python may allow a remote attacker, who controls the HTTP server, to make the client script enter an infinite loop, consuming CPU time. The highest threat from this vulnerability is to system availability."
                }
            ],
            "affected": [
                {
                    "vendor": "n/a",
                    "product": "python",
                    "versions": [
                        {
                            "version": "Fixed in python v3.6.14, python v3.7.11, python v3.8.11, python v3.9.6, python v3.10.0b2",
                            "status": "affected"
                        }
                    ]
                }
            ],
            "references": [
                {
                    "url": "https://bugs.python.org/issue44022"
                },
                {
                    "url": "https://github.com/python/cpython/pull/25916"
                },
                {
                    "url": "https://bugzilla.redhat.com/show_bug.cgi?id=1995162"
                },
                {
                    "url": "https://github.com/python/cpython/pull/26503"
                },
                {
                    "url": "https://ubuntu.com/security/CVE-2021-3737"
                },
                {
                    "url": "https://www.oracle.com/security-alerts/cpujul2022.html"
                },
                {
                    "url": "https://python-security.readthedocs.io/vuln/urllib-100-continue-loop.html"
                },
                {
                    "url": "https://security.netapp.com/advisory/ntap-20220407-0009/"
                },
                {
                    "name": "[debian-lts-announce] 20230524 [SECURITY] [DLA 3432-1] python2.7 security update",
                    "tags": [
                        "mailing-list"
                    ],
                    "url": "https://lists.debian.org/debian-lts-announce/2023/05/msg00024.html"
                },
                {
                    "name": "[debian-lts-announce] 20230630 [SECURITY] [DLA 3477-1] python3.7 security update",
                    "tags": [
                        "mailing-list"
                    ],
                    "url": "https://lists.debian.org/debian-lts-announce/2023/06/msg00039.html"
                }
            ],
            "problemTypes": [
                {
                    "descriptions": [
                        {
                            "type": "CWE",
                            "lang": "en",
                            "description": "CWE-835 - Loop with Unreachable Exit Condition ('Infinite Loop'), CWE-400 - Uncontrolled Resource Consumption",
                            "cweId": "CWE-835"
                        }
                    ]
                }
            ]
        }
    }
}